<mujoco model="2f85 scene">

  <size memory="100M"/>

  <compiler angle="radian" meshdir="assets" autolimits="true"/>
  
  <extension>
    <plugin plugin="mujoco.sensor.touch_grid"/>
  </extension>

  <option impratio="0.1"/>
  
  <asset>
    <material name="metal" rgba="0.58 0.58 0.58 1"/>
    <material name="silicone" rgba="0.1882 0.1882 0.1882 1"/>
    <material name="gray" rgba="0.4627 0.4627 0.4627 1"/>
    <material name="black" rgba="0.149 0.149 0.149 1"/>

    <mesh class="2f85" file="base_mount.stl"/>
    <mesh class="2f85" file="base.stl"/>
    <mesh class="2f85" file="driver.stl"/>
    <mesh class="2f85" file="coupler.stl"/>
    <mesh class="2f85" file="follower.stl"/>
    <mesh class="2f85" file="pad.stl"/>
    <mesh class="2f85" file="silicone_pad.stl"/>
    <mesh class="2f85" file="spring_link.stl"/>

    <mesh class="objects" name="holder1" file="holder1.stl"/>
    <mesh class="objects" name="holder2" file="holder2.stl"/>
    <mesh class="objects" name="holder3" file="holder3.stl"/>
    <mesh class="objects" name="triangle" file="triangle.stl"/>
    <mesh class="objects" file="triangle_wall1.stl"/>
    <mesh class="objects" file="triangle_wall2.stl"/>
    <mesh class="objects" file="triangle_wall3.stl"/>
    <mesh class="objects" file="triangle_wall4.stl"/>
    <mesh class="objects" name="square" file="square.stl"/>
    <mesh class="objects" file="square_wall1.stl"/>
    <mesh class="objects" file="square_wall2.stl"/>
    <mesh class="objects" file="square_wall3.stl"/>
    <mesh class="objects" file="square_wall4.stl"/>
    <mesh class="objects" name="rectangle" file="rectangle.stl"/>
    <mesh class="objects" file="rectangle_wall1.stl"/>
    <mesh class="objects" file="rectangle_wall2.stl"/>
    <mesh class="objects" file="rectangle_wall3.stl"/>
    <mesh class="objects" file="rectangle_wall4.stl"/>
    <mesh class="objects" name="horizontal" file="horizontal.stl"/>
    <mesh class="objects" file="horizontal_wall1.stl"/>
    <mesh class="objects" file="horizontal_wall2.stl"/>
    <mesh class="objects" file="horizontal_wall3.stl"/>
    <mesh class="objects" file="horizontal_wall4.stl"/>
    <mesh class="objects" name="vertical" file="vertical.stl"/>
    <mesh class="objects" file="vertical_wall1.stl"/>
    <mesh class="objects" file="vertical_wall2.stl"/>
    <mesh class="objects" file="vertical_wall3.stl"/>
    <mesh class="objects" file="vertical_wall4.stl"/>
    <mesh class="objects" name="trapezoidal" file="trapezoidal.stl"/>
    <mesh class="objects" file="trapezoidal_wall1.stl"/>
    <mesh class="objects" file="trapezoidal_wall2.stl"/>
    <mesh class="objects" file="trapezoidal_wall3.stl"/>
    <mesh class="objects" file="trapezoidal_wall4.stl"/>
    <mesh class="objects" name="rhombus" file="rhombus.stl"/>
    <mesh class="objects" file="rhombus_wall1.stl"/>
    <mesh class="objects" file="rhombus_wall2.stl"/>
    <mesh class="objects" file="rhombus_wall3.stl"/>
    <mesh class="objects" file="rhombus_wall4.stl"/>

  </asset>

  <default>
    <default class="objects">
      <mesh scale="0.001 0.001 0.001"/>
    </default>
    <default class="2f85">
      <mesh scale="0.001 0.001 0.001"/>
      <general biastype="affine"/>

      <joint axis="1 0 0"/>
      <default class="driver">
        <joint range="0 0.8" armature="0.005" damping="0.1" solimplimit="0.95 0.99 0.001" solreflimit="0.005 1"/>
      </default>
      <default class="follower">
        <joint range="-0.872664 0.872664" pos="0 -0.018 0.0065" solimplimit="0.95 0.99 0.001" solreflimit="0.005 1" armature="0.001"/>
      </default>
      <default class="spring_link">
        <joint range="-0.29670597283 0.8" stiffness="0.05" springref="2.62" damping="0.000125" armature="0.001"/>
      </default>
      <default class="coupler">
        <joint range="-1.57 0" solimplimit="0.95 0.99 0.001" solreflimit="0.005 1" armature="0.001"/>
      </default>

      <default class="visual">
        <geom type="mesh" contype="0" conaffinity="0" group="2"/>
      </default>
      <default class="collision">
        <geom type="mesh" group="3"/>
        <default class="pad"> <geom mass="0" type="box" friction="0.9" solimp="0.98 0.99 0.001" solref="0.004 1" priority="1"/> </default>
      </default>
    </default>
  </default>

  <worldbody>
    <body name="base_mount" pos="0 0 0.3" zaxis="0 0 -1" childclass="2f85" gravcomp="1">
      <joint name="base_mount_joint_x" type="slide" pos="0 0 0.3" axis="1 0 0" damping="18" range="-1 1"/>
      <joint name="base_mount_joint_y" type="slide" pos="0 0 0.3" axis="0 -1 0" damping="18" range="-1 1"/>
      <joint name="base_mount_joint_z" type="slide" pos="0 0 0.3" axis="0 0 -1" damping="18" range="-1 1"/>
      <joint name="base_mount_joint_yaw" type="hinge" pos="0 0 0.3" axis="0 0 1" damping="0.05" range="-3.14159 3.14159"/>
      <geom class="visual" mesh="base_mount" material="black"/>
      <geom class="collision" mesh="base_mount"/>
      <body name="base" pos="0 0 0.0038" quat="1 0 0 -1" gravcomp="1">
        <inertial mass="0.777441" pos="0 -2.70394e-05 0.0354675" quat="1 -0.00152849 0 0"
          diaginertia="0.000260285 0.000225381 0.000152708"/>
        <geom class="visual" mesh="base" material="black"/>
        <geom class="collision" mesh="base"/>
        <site name="pinch" pos="0 0 0.145" type="sphere" group="5" rgba="0.9 0.9 0.9 1" size="0.005"/>
        <!-- Right-hand side 4-bar linkage -->
        <body name="right_driver" pos="0 0.0306011 0.054904" gravcomp="1">
          <inertial mass="0.00899563" pos="2.96931e-12 0.0177547 0.00107314" quat="0.681301 0.732003 0 0"
            diaginertia="1.72352e-06 1.60906e-06 3.22006e-07"/>
          <joint name="right_driver_joint" class="driver"/>
          <geom class="visual" mesh="driver" material="gray"/>
          <geom class="collision" mesh="driver"/>
          <body name="right_coupler" pos="0 0.0315 -0.0041" gravcomp="1">
            <inertial mass="0.0140974" pos="0 0.00301209 0.0232175" quat="0.705636 -0.0455904 0.0455904 0.705636"
              diaginertia="4.16206e-06 3.52216e-06 8.88131e-07"/>
            <joint name="right_coupler_joint" class="coupler"/>
            <geom class="visual" mesh="coupler" material="black"/>
            <geom class="collision" mesh="coupler"/>
          </body>
        </body>
        <body name="right_spring_link" pos="0 0.0132 0.0609" gravcomp="1">
          <inertial mass="0.0221642" pos="-8.65005e-09 0.0181624 0.0212658" quat="0.663403 -0.244737 0.244737 0.663403"
            diaginertia="8.96853e-06 6.71733e-06 2.63931e-06"/>
          <joint name="right_spring_link_joint" class="spring_link"/>
          <geom class="visual" mesh="spring_link" material="black"/>
          <geom class="collision" mesh="spring_link"/>
          <body name="right_follower" pos="0 0.055 0.0375" gravcomp="1">
            <inertial mass="0.0125222" pos="0 -0.011046 0.0124786" quat="1 0.1664 0 0"
              diaginertia="2.67415e-06 2.4559e-06 6.02031e-07"/>
            <joint name="right_follower_joint" class="follower"/>
            <geom class="visual" mesh="follower" material="black"/>
            <geom class="collision" mesh="follower"/>
            <body name="right_pad" pos="0 -0.0189 0.01352" gravcomp="1">
              <include file="right_pad_collisions.xml"/>
              <inertial mass="0.0035" pos="0 -0.0025 0.0185" quat="0.707107 0 0 0.707107"
              diaginertia="4.73958e-07 3.64583e-07 1.23958e-07"/>
              <geom class="visual" mesh="pad"/>
              <body name="right_silicone_pad" gravcomp="1">
              <geom class="visual" mesh="silicone_pad" material="black"/>
              <site name="touch_right" pos="0 0.04 0.018" zaxis="0 1 0" rgba="0 0 1 0"/>
              </body>
          </body>
          </body>
        </body>
        <!-- Left-hand side 4-bar linkage -->
        <body name="left_driver" pos="0 -0.0306011 0.054904" quat="0 0 0 1" gravcomp="1">
          <inertial mass="0.00899563" pos="0 0.0177547 0.00107314" quat="0.681301 0.732003 0 0"
            diaginertia="1.72352e-06 1.60906e-06 3.22006e-07"/>
          <joint name="left_driver_joint" class="driver"/>
          <geom class="visual" mesh="driver" material="gray"/>
          <geom class="collision" mesh="driver"/>
          <body name="left_coupler" pos="0 0.0315 -0.0041" gravcomp="1">
            <inertial mass="0.0140974" pos="0 0.00301209 0.0232175" quat="0.705636 -0.0455904 0.0455904 0.705636"
              diaginertia="4.16206e-06 3.52216e-06 8.88131e-07"/>
            <joint name="left_coupler_joint" class="coupler"/>
            <geom class="visual" mesh="coupler" material="black"/>
            <geom class="collision" mesh="coupler"/>
          </body>
        </body>
        <body name="left_spring_link" pos="0 -0.0132 0.0609" quat="0 0 0 1" gravcomp="1">
          <inertial mass="0.0221642" pos="-8.65005e-09 0.0181624 0.0212658" quat="0.663403 -0.244737 0.244737 0.663403"
            diaginertia="8.96853e-06 6.71733e-06 2.63931e-06"/>
          <joint name="left_spring_link_joint" class="spring_link"/>
          <geom class="visual" mesh="spring_link" material="black"/>
          <geom class="collision" mesh="spring_link"/>
          <body name="left_follower" pos="0 0.055 0.0375" gravcomp="1">
            <inertial mass="0.0125222" pos="0 -0.011046 0.0124786" quat="1 0.1664 0 0"
              diaginertia="2.67415e-06 2.4559e-06 6.02031e-07"/>
            <joint name="left_follower_joint" class="follower"/>
            <geom class="visual" mesh="follower" material="black"/>
            <geom class="collision" mesh="follower"/>
            <body name="left_pad" pos="0 -0.0189 0.01352" gravcomp="1">
              <include file="left_pad_collisions.xml"/>
              <inertial mass="0.0035" pos="0 -0.0025 0.0185" quat="1 0 0 1"
              diaginertia="4.73958e-07 3.64583e-07 1.23958e-07"/>
              <geom class="visual" mesh="pad"/>
              <body name="left_silicone_pad" gravcomp="1">
              <geom class="visual" mesh="silicone_pad" material="black"/>
              <site name="touch_left" pos="0 0.04 0.018" zaxis="0 1 0" rgba="0 0 1 0"/>
              </body>
          </body>
          </body>
        </body>
      </body>
    </body>
  </worldbody>

  <contact>
    <exclude body1="base" body2="left_driver"/>
    <exclude body1="base" body2="right_driver"/>
    <exclude body1="base" body2="left_spring_link"/>
    <exclude body1="base" body2="right_spring_link"/>
    <exclude body1="right_coupler" body2="right_follower"/>
    <exclude body1="left_coupler" body2="left_follower"/>
  </contact>

  <!--
    This adds stability to the model by having a tendon that distributes the forces between both
    joints, such that the equality constraint doesn't have to do that much work in order to equalize
    both joints. Since both joints share the same sign, we split the force between both equally by
    setting coef=0.5
  -->
  <tendon>
    <fixed name="split">
      <joint joint="right_driver_joint" coef="0.5"/>
      <joint joint="left_driver_joint" coef="0.5"/>
    </fixed>
  </tendon>

  <equality>
    <connect anchor="0 0 0" body1="right_follower" body2="right_coupler" solimp="0.95 0.99 0.001" solref="0.005 1"/>
    <connect anchor="0 0 0" body1="left_follower" body2="left_coupler" solimp="0.95 0.99 0.001" solref="0.005 1"/>
    <joint joint1="right_driver_joint" joint2="left_driver_joint" polycoef="0 1 0 0 0" solimp="0.95 0.99 0.001"
      solref="0.005 1"/>
  </equality>

  <actuator>
    <position class="2f85" name="base_actuator_x" joint="base_mount_joint_x" ctrlrange="-1 1" kp="100"/>
  </actuator>
  <actuator>
    <position class="2f85" name="base_actuator_y" joint="base_mount_joint_y" ctrlrange="-1 1" kp="100"/>
  </actuator>
  <actuator>
    <position class="2f85" name="base_actuator_z" joint="base_mount_joint_z" ctrlrange="-1 1" kp="100"/>
  </actuator>
  <actuator>
    <position class="2f85" name="base_actuator_yaw" joint="base_mount_joint_yaw" ctrlrange="-3.14159 3.14159" kp="0.5"/>
  </actuator>

  <!--
    The general actuator below is a customized position actuator (with some damping) where
    gainprm[0] != kp (see http://mujoco.org/book/modeling.html#position).
    The reason why gainprm[0] != kp is because the control input range has to be re-scaled to
    [0, 255]. The joint range is currently set at [0, 0.8], the control range is [0, 255] and
    kp = 100. Tau = Kp * scale * control_input - Kp * error, max(Kp * scale * control_input) = 0.8,
    hence scale = 0.8 * 100 / 255
  -->
  <actuator>
    <general class="2f85" name="fingers_actuator" tendon="split" forcerange="-5 80" ctrlrange="0 255"
      gainprm="0.31372549 0 0" biasprm="0 -100 -10"/>
  </actuator>

  <include file="touch_sensors.xml"/>

  <statistic center="0 0 0.05" extent="0.3"/>


  <visual>
    <headlight diffuse="0.6 0.6 0.6" ambient="0.3 0.3 0.3" specular="0 0 0"/>
    <rgba haze="0.15 0.25 0.35 1"/>
    <global azimuth="60" elevation="-20"/>
  </visual>

  <asset>
    <texture type="skybox" builtin="gradient" rgb1="0.3 0.5 0.7" rgb2="0 0 0" width="512" height="3072"/>
    <texture type="2d" name="groundplane" builtin="checker" mark="edge" rgb1="0.2 0.3 0.4" rgb2="0.1 0.2 0.3"
      markrgb="0.8 0.8 0.8" width="300" height="300"/>
    <material name="groundplane" texture="groundplane" texuniform="true" texrepeat="5 5" reflectance="0.2"/>
  </asset>

  <worldbody>
    <light pos="0 0 1"/>
    <light pos="0 -0.2 1" dir="0 0.2 -0.8" directional="true"/>
    <camera pos="-0.119 -0.187 0.274" xyaxes="0.853 -0.522 0.000 0.353 0.577 0.737"/>
    <camera pos="-0.352 -0.497 0.660" xyaxes="0.816 -0.578 -0.000 0.409 0.578 0.707"/>
    <camera pos="0.0 0.0 0.9" xyaxes="1.000 0 -0.000 0.00 1.000 0.00"/>
    <camera pos="0.0 0.0 0.5" xyaxes="1.000 0 -0.000 0.00 1.000 0.00"/>
    <geom name="floor" size="0 0 0.05" type="plane" material="groundplane"/>
    <body name="object" pos="0. 0 0." axisangle="0 0 1 0.0">
      <joint type="free" name="object_jnt"/>
      <geom class="visual" name="peg_visual" mesh="triangle" rgba="0.8 0.8 0.1 1" friction=".8"/>
      <geom class="collision" name="peg_collision" mesh="triangle" friction=".8"/>
      <geom class="visual" name="holder_visual" mesh="holder1" rgba="0.8 0.8 0.1 1" friction=".5"/>
      <geom class="collision" name="holder_collision" mesh="holder1" friction=".5"/>
    </body>
    <body name="walls" pos="0 0 0.00" axisangle="0 0 1 0.0">
      <geom class="visual" name="wall1_visual" mesh="triangle_wall1" rgba="0.5 0.5 0.5 1" friction=".3" priority="1" solref="0.007 1"/>
      <geom class="collision" name="wall1_collision" mesh="triangle_wall1" friction=".3" priority="1" solref="0.007 1"/>
      <geom class="visual" name="wall2_visual" mesh="triangle_wall2" rgba="0.5 0.5 0.5 1" friction=".3" priority="1" solref="0.007 1"/>
      <geom class="collision" name="wall2_collision" mesh="triangle_wall2" friction=".3" priority="1" solref="0.007 1"/>
      <geom class="visual" name="wall3_visual" mesh="triangle_wall3" rgba="0.5 0.5 0.5 1" friction=".3" priority="1" solref="0.007 1"/>
      <geom class="collision" name="wall3_collision" mesh="triangle_wall3" friction=".3" priority="1" solref="0.007 1"/>
      <geom class="visual" name="wall4_visual" mesh="triangle_wall4" rgba="0.5 0.5 0.5 1" friction=".3" priority="1" solref="0.007 1"/>
      <geom class="collision" name="wall4_collision" mesh="triangle_wall4" friction=".3" priority="1" solref="0.007 1"/>
    </body>
    
  </worldbody>

  <keyframe>
  <key qpos='7.97928e-17 1.64512e-15 -0.015679 -6.94034e-17 0.533632 -0.0232536 0.502887 -0.508944 0.533632 -0.0232356 0.502907 -0.508956 8.63304e-07 -0.00141601 0.0898405 1 3.43207e-05 -1.99481e-06 -5.93085e-11' ctrl='0 0 0 0 200'/>
  </keyframe>

</mujoco>
